<?xml version="1.0"?>
<robot xmlns:xacro="http://www.ros.org/wiki/xacro" name="mpav">
<xacro:include filename="$(find krishaka)/urdf/new_depth_camera.gazebo.xacro"/>

<link name="base_footprint"/>

<link name="base_link">
    <inertial>
        <origin xyz="0.0 0.0 0.0" rpy="0.0 0.0 0.0"/>
        <mass value="1.0"/>
        <inertia ixx="0.3" ixy="0.0" ixz="0.0"
                 iyy="0.3" iyz="0.0"
                 izz="0.3"/>
    </inertial>
    <visual name="">
        <origin xyz="0.0 0.0 0.0" rpy="0.0 0.0 0.0"/>
        <geometry>
            <box size="1 0.7 0.1"/>
        </geometry>
        <material name="">
            <color rgba="1.0 0.0 0.0 1.0"/>
            <texture filename=""/>
        </material>
    </visual>
    <collision>
        <origin xyz="0.0 0.0 0.0" rpy="0.0 0.0 0.0"/>
        <geometry>
            <box size="1 0.7 0.1"/>
        </geometry>
    </collision>
</link>

<joint name="base_joint" type="fixed">
    <origin xyz="0.0 0.0 0.7" rpy="0.0 0.0 0.0"/>
    <parent link="base_footprint"/>
    <child link="base_link"/>
    <axis xyz="0.0 0.0 0.0"/>
</joint>

<gazebo reference="base_link">
    <turnGravityOff>false</turnGravityOff>
</gazebo>

<link name="front_left_link">
    <inertial>
        <origin xyz="0.0 0.0 0.0" rpy="0.0 0.0 0.0"/>
        <mass value="1"/>
        <inertia ixx="0.3" ixy="0.0" ixz="0.0"
                 iyy="0.3" iyz="0.0"
                 izz="0.3"/>
    </inertial>
    <visual name="">
        <origin xyz="0.0 0.0 0.0" rpy="0.0 0.0 0.0"/>
        <geometry>
            <box size="0.01 0.01 0.5"/>
        </geometry>
        <material name="">
            <color rgba="1.0 0.0 0.0 1.0"/>
            <texture filename=""/>
        </material>
    </visual>
    <collision>
        <origin xyz="0.0 0.0 0.0" rpy="0.0 0.0 0.0"/>
        <geometry>
            <box size="0.01 0.01 0.5"/>
        </geometry>
    </collision>
</link>

<joint name="side_joint_1" type="fixed">
    <origin xyz="0.5 0.35 -0.25" rpy="0.0 0.0 0.0"/>
    <parent link="base_link"/>
    <child link="front_left_link"/>
    <axis xyz="0.0 0.0 0.0"/>
</joint>
<gazebo reference="front_left_link">
    <turnGravityOff>false</turnGravityOff>
</gazebo>


<link name="rear_left_link">
    <inertial>
        <origin xyz="0.0 0.0 0.0" rpy="0.0 0.0 0.0"/>
        <mass value="1"/>
        <inertia ixx="0.3" ixy="0.0" ixz="0.0"
                 iyy="0.3" iyz="0.0"
                 izz="0.3"/>
    </inertial>
    <visual name="">
        <origin xyz="0.0 0.0 0.0" rpy="0.0 0.0 0.0"/>
        <geometry>
            <box size="0.01 0.01 0.5"/>
        </geometry>
        <material name="">
            <color rgba="1.0 0.0 0.0 1.0"/>
            <texture filename=""/>
        </material>
    </visual>
    <collision>
        <origin xyz="0.0 0.0 0.0" rpy="0.0 0.0 0.0"/>
        <geometry>
            <box size="0.01 0.01 0.5"/>
        </geometry>
    </collision>
</link>

<joint name="side_joint_2" type="fixed">
    <origin xyz="-0.5 0.35 -0.25" rpy="0.0 0.0 0.0"/>
    <parent link="base_link"/>
    <child link="rear_left_link"/>
    <axis xyz="0.0 0.0 0.0"/>
</joint>
<gazebo reference="rear_left_link">
    <turnGravityOff>false</turnGravityOff>
</gazebo>

<link name="rear_right_link">
    <inertial>
        <origin xyz="0.0 0.0 0.0" rpy="0.0 0.0 0.0"/>
        <mass value="1"/>
        <inertia ixx="0.3" ixy="0.0" ixz="0.0"
                 iyy="0.3" iyz="0.0"
                 izz="0.3"/>
    </inertial>
    <visual name="">
        <origin xyz="0.0 0.0 0.0" rpy="0.0 0.0 0.0"/>
        <geometry>
            <box size="0.01 0.01 0.5"/>
        </geometry>
        <material name="">
            <color rgba="1.0 0.0 0.0 1.0"/>
            <texture filename=""/>
        </material>
    </visual>
    <collision>
        <origin xyz="0.0 0.0 0.0" rpy="0.0 0.0 0.0"/>
        <geometry>
            <box size="0.01 0.01 0.5"/>
        </geometry>
    </collision>
</link>

<joint name="side_joint_3" type="fixed">
    <origin xyz="-0.5 -0.35 -0.25" rpy="0.0 0.0 0.0"/>
    <parent link="base_link"/>
    <child link="rear_right_link"/>
    <axis xyz="0.0 0.0 0.0"/>
</joint>
<gazebo reference="rear_right_link">
    <turnGravityOff>false</turnGravityOff>
</gazebo>

<link name="rear_front_link">
    <inertial>
        <origin xyz="0.0 0.0 0.0" rpy="0.0 0.0 0.0"/>
        <mass value="1"/>
        <inertia ixx="0.3" ixy="0.0" ixz="0.0"
                 iyy="0.3" iyz="0.0"
                 izz="0.3"/>
    </inertial>
    <visual name="">
        <origin xyz="0.0 0.0 0.0" rpy="0.0 0.0 0.0"/>
        <geometry>
            <box size="0.01 0.01 0.5"/>
        </geometry>
        <material name="">
            <color rgba="1.0 0.0 0.0 1.0"/>
            <texture filename=""/>
        </material>
    </visual>
    <collision>
        <origin xyz="0.0 0.0 0.0" rpy="0.0 0.0 0.0"/>
        <geometry>
            <box size="0.01 0.01 0.5"/>
        </geometry>
    </collision>
</link>

<joint name="side_joint_4" type="fixed">
    <origin xyz="0.5 -0.36 -0.25" rpy="0.0 0.0 0.0"/>
    <parent link="base_link"/>
    <child link="rear_front_link"/>
    <axis xyz="0.0 0.0 0.0"/>
</joint>
<gazebo reference="rear_front_link">
    <turnGravityOff>false</turnGravityOff>
</gazebo>

<!-- All Wheel links and joints -->


<xacro:macro name="wheel" params="name x y">

    <link name="wheel_${name}_link">
        <inertial>
            <origin xyz="0.0 0.0 0.0" rpy="0.0 0.0 0.0"/>
            <mass value="0.5"/>
            <inertia ixx="0.0" ixy="0.0" ixz="0.0" iyy="0.0" iyz="0.0" izz="0.0"/>
        </inertial>
        <visual name="">
            <origin xyz="0.0 0.0 0.0" rpy="0.0 0.0 0.0"/>
            <geometry>
                <cylinder radius="0.25" length="0.05"/>
            </geometry>
            <material name="black">
                <color rgba=".0 .0 0.0 1.0"/>
            </material>
        </visual>
        <collision>
            <origin xyz="0.0 0.0 0.0" rpy="0.0 0.0 0.0"/>
            <geometry>
                <cylinder radius="0.25" length="0.05"/>
            </geometry>
        </collision>
    </link>

    <joint name="wheel_${name}_joint" type="continuous">
        <origin xyz="${x} ${y} -0.50" rpy="1.57 0.0 0.0"/>
        <parent link="base_link"/>
        <child link="wheel_${name}_link"/>
        <axis xyz=".0 0.0 1.0"/>
        <limit effort= "100" velocity="100"/>
        <dynamics damping="0.0" friction="0.0"/>
    </joint>

    

    <gazebo reference ="wheel_${name}">
    <mu1 value="200.0"/>
    <mu2 value="100.0"/>
    <kp value="10000000.0"/>
    <kd value= "1.0"/>
    <material>Gazebo/Black</material>
  </gazebo>

</xacro:macro>

<xacro:wheel name="front_left"  x="0.50" y =" 0.38"/>
<xacro:wheel name="rear_left" x="-0.50" y =" 0.38"/>
<xacro:wheel name="rear_right"  x="-0.50" y =" -0.38"/>
<xacro:wheel name="front_right"   x="0.50" y =" -0.38"/>

<!--Plugins-->
  <gazebo>
  <plugin name="gazebo_ros_control" filename="libgazebo_ros_control.so">
    <robotNamespace>/your_robot_name</robotNamespace>
    <!-- Other controller parameters -->
  </plugin>

  <plugin name="differential_drive_controller" filename="libgazebo_ros_diff_drive.so">
    <leftJoint>wheel_rear_left_joint</leftJoint>
    <rightJoint>wheel_rear_right_joint</rightJoint>
    <wheelSeparation>0.5</wheelSeparation>  
    <wheelDiameter>0.4</wheelDiameter>      
    <publishWheelJointState>true</publishWheelJointState>
  </plugin>

  <plugin name="gazebo_ros_pose" filename="libgazebo_ros_pose.so">
        <bodyName>base_link</bodyName>
        <topicName>robot_pose</topicName>
        <updateRate>50</updateRate>
    </plugin>

  </gazebo>


</robot>